<?xml version="1.0" ?>
<!-- =================================================================================== -->
<!-- |    This document was autogenerated by xacro from robot.xacro                    | -->
<!-- |    EDITING THIS FILE BY HAND IS NOT RECOMMENDED                                 | -->
<!-- =================================================================================== -->
<robot name="robot">
  <gazebo reference="body_link">
    <kp>1000000.0</kp>
    <kd>100.0</kd>
    <mu1>1.0</mu1>
    <mu2>1.0</mu2>
    <material>Gazebo/Red</material>
  </gazebo>
  <gazebo reference="wheel1_link">
    <kp>1000000.0</kp>
    <kd>100.0</kd>
    <mu1>1.0</mu1>
    <mu2>1.0</mu2>
    <material>Gazebo/Yellow</material>
  </gazebo>
  <gazebo reference="wheel2_link">
    <kp>1000000.0</kp>
    <kd>100.0</kd>
    <mu1>1.0</mu1>
    <mu2>1.0</mu2>
    <material>Gazebo/Yellow</material>
  </gazebo>
  <gazebo reference="wheel3_link">
    <kp>1000000.0</kp>
    <kd>100.0</kd>
    <mu1>1.0</mu1>
    <mu2>1.0</mu2>
    <material>Gazebo/Yellow</material>
  </gazebo>
  <gazebo reference="wheel4_link">
    <kp>1000000.0</kp>
    <kd>100.0</kd>
    <mu1>1.0</mu1>
    <mu2>1.0</mu2>
    <material>Gazebo/Yellow</material>
  </gazebo>
  <ros2_control name="GazeboSystem" type="system">
    <hardware>
      <plugin>gazebo_ros2_control/GazeboSystem</plugin>
    </hardware>
    <!-- <joint name="wheel1_joint">
        <command_interface name="position">
            <param name="min">-6.2832</param>
            <param name="max">6.2832</param>
        </command_interface>
        <state_interface name="position" />
        <state_interface name="velocity" />
        <state_interface name="effort" />
    </joint> -->
  </ros2_control>
  <gazebo>
    <plugin filename="libgazebo_ros2_control.so" name="gazebo_ros2_control">
      <!-- <robot_sim_type>gazebo_ros2_control/DefaultRobotHWSim</robot_sim_type> -->
      <robot_sim_type>gazebo_ros2_control/GazeboSystem</robot_sim_type>
      <parameters>/home/a/robotics-lab/final-project/robotics-assignment/ros_ws/src/simple_robot_description/config/robot.yaml</parameters>
    </plugin>
  </gazebo>
  <gazebo>
    <plugin filename="libgazebo_ros_diff_drive.so" name="skid_steer_drive_controller">
      <update_rate>500</update_rate>
      <num_wheel_pairs>2</num_wheel_pairs>
      <left_joint>wheel2_joint</left_joint>
      <right_joint>wheel1_joint</right_joint>
      <left_joint>wheel4_joint</left_joint>
      <right_joint>wheel3_joint</right_joint>
      <wheel_separation>0.7</wheel_separation>
      <wheel_separation>0.7</wheel_separation>
      <wheel_diameter>0.3</wheel_diameter>
      <wheel_diameter>0.3</wheel_diameter>
      <max_wheel_torque>200</max_wheel_torque>
      <max_wheel_acceleration>10.0</max_wheel_acceleration>
      <command_topic>cmd_vel</command_topic>
      <odometry_topic>odom</odometry_topic>
      <odometry_frame>odom</odometry_frame>
      <robot_base_frame>dummy</robot_base_frame>
      <publish_wheel_tf>true</publish_wheel_tf>
      <publish_odom>true</publish_odom>
      <covariance_x>0.0001</covariance_x>
      <covariance_y>0.0001</covariance_y>
      <covariance_yaw>0.01</covariance_yaw>
    </plugin>
  </gazebo>
  <!-- Link and Joints -->
  <link name="dummy"/>
  <joint name="dummy_joint" type="fixed">
    <parent link="dummy"/>
    <child link="body_link"/>
  </joint>
  <link name="body_link">
    <visual>
      <geometry>
        <box size="1 0.6 0.3"/>
      </geometry>
      <origin rpy="0 0 0" xyz="0 0 0.25"/>
    </visual>
    <collision>
      <geometry>
        <box size="1 0.6 0.3"/>
      </geometry>
      <origin rpy="0 0 0" xyz="0 0 0.25"/>
    </collision>
    <inertial>
      <origin rpy="0 0 0" xyz="0 0 0.25"/>
      <mass value="487.79999999999995"/>
      <inertia ixx="18.292499999999993" ixy="0" ixz="0" iyy="44.308499999999995" iyz="0" izz="55.283999999999985"/>
    </inertial>
  </link>
  <!-- Back right wheel -->
  <joint name="wheel1_joint" type="continuous">
    <parent link="body_link"/>
    <child link="wheel1_link"/>
    <origin rpy="0 0 0" xyz="-0.32 -0.375 0.1"/>
    <axis xyz="0 1 0"/>
    <limit effort="1000" velocity="1000"/>
    <dynamics damping="1.0" friction="1.0"/>
  </joint>
  <link name="wheel1_link">
    <visual>
      <origin rpy="1.570795 0 0" xyz="0 0 0"/>
      <geometry>
        <cylinder length="0.1" radius="0.15"/>
      </geometry>
    </visual>
    <collision>
      <origin rpy="1.570795 0 0" xyz="0 0 0"/>
      <geometry>
        <cylinder length="0.1" radius="0.15"/>
      </geometry>
    </collision>
    <inertial>
      <origin rpy="0 0 0" xyz="0 0 0"/>
      <mass value="19.155861183375002"/>
      <inertia ixx="-0.5267861825428125" ixy="0" ixz="0.0" iyy="-0.5267861825428125" iyz="0" izz="0.21550343831296875"/>
    </inertial>
  </link>
  <!-- Back left wheel -->
  <joint name="wheel2_joint" type="continuous">
    <parent link="body_link"/>
    <child link="wheel2_link"/>
    <origin rpy="0 0 0" xyz="-0.32 0.22499999999999998 0.1"/>
    <axis xyz="0 1 0"/>
    <limit effort="1000" velocity="1000"/>
    <dynamics damping="1.0" friction="1.0"/>
  </joint>
  <link name="wheel2_link">
    <visual>
      <origin rpy="1.570795 0 0" xyz="0 0 0"/>
      <geometry>
        <cylinder length="0.1" radius="0.15"/>
      </geometry>
    </visual>
    <collision>
      <origin rpy="1.570795 0 0" xyz="0 0 0"/>
      <geometry>
        <cylinder length="0.1" radius="0.15"/>
      </geometry>
    </collision>
    <inertial>
      <origin rpy="0 0 0" xyz="0 0 0"/>
      <mass value="19.155861183375002"/>
      <inertia ixx="-0.5267861825428125" ixy="0" ixz="0.0" iyy="-0.5267861825428125" iyz="0" izz="0.21550343831296875"/>
    </inertial>
  </link>
  <!-- Front right wheel -->
  <joint name="wheel3_joint" type="continuous">
    <parent link="body_link"/>
    <child link="wheel3_link"/>
    <origin rpy="0 0 0" xyz="0.32 -0.375 0.1"/>
    <axis xyz="0 1 0"/>
    <limit effort="1000" velocity="1000"/>
    <dynamics damping="1.0" friction="1.0"/>
  </joint>
  <link name="wheel3_link">
    <visual>
      <origin rpy="1.570795 0 0" xyz="0 0 0"/>
      <geometry>
        <cylinder length="0.1" radius="0.15"/>
      </geometry>
    </visual>
    <collision>
      <origin rpy="1.570795 0 0" xyz="0 0 0"/>
      <geometry>
        <cylinder length="0.1" radius="0.15"/>
      </geometry>
    </collision>
    <inertial>
      <origin rpy="0 0 0" xyz="0 0 0"/>
      <mass value="19.155861183375002"/>
      <inertia ixx="-0.5267861825428125" ixy="0" ixz="0.0" iyy="-0.5267861825428125" iyz="0" izz="0.21550343831296875"/>
    </inertial>
  </link>
  <!-- Front left wheel -->
  <joint name="wheel4_joint" type="continuous">
    <parent link="body_link"/>
    <child link="wheel4_link"/>
    <origin rpy="0 0 0" xyz="0.32 0.375 0.1"/>
    <axis xyz="0 1 0"/>
    <limit effort="1000" velocity="1000"/>
    <dynamics damping="1.0" friction="1.0"/>
  </joint>
  <link name="wheel4_link">
    <visual>
      <origin rpy="1.570795 0 0" xyz="0 0 0"/>
      <geometry>
        <cylinder length="0.1" radius="0.15"/>
      </geometry>
    </visual>
    <collision>
      <origin rpy="1.570795 0 0" xyz="0 0 0"/>
      <geometry>
        <cylinder length="0.1" radius="0.15"/>
      </geometry>
    </collision>
    <inertial>
      <origin rpy="0 0 0" xyz="0 0 0"/>
      <mass value="19.155861183375002"/>
      <inertia ixx="-0.5267861825428125" ixy="0" ixz="0.0" iyy="-0.5267861825428125" iyz="0" izz="0.21550343831296875"/>
    </inertial>
  </link>
</robot>
